Workbook

Sheet README
A1: Observed time-and-motion log — autofmu workflow effort
A3: This workbook is EMPTY BY DESIGN. Nothing in it is an estimate. Every number in Summary is a formula over what you type into Log.
A5: Field | B5: Definition
A6: Evidence status | B6: OBSERVED (manual arm only). Recorded live 2026-06-06 to 2026-06-23 across 13 working days by one operator. The Auto rows are deliberately EMPTY: that arm has not been logged, so no effort-reduction figure may be taken from this file.
A7: Supersedes | B7: time_and_motion_study_20260803/time_and_motion_study_simulated_pilot.xlsx, which is a simulated pilot by its own declaration and reconstructs the published 115.0 h / 13.6 h figures rather than testing them.
A8: Sampling frame | B8: autofmu run sitea_e2e_20260804c — Site A, 34 devices (7 chillers, 7 cooling towers, 17 pumps, 3 heat exchangers).
A9: Sample | B9: Two accepted devices and one refused device per family, 12 in total. See the Sample sheet for why each was chosen.
A10: Families | B10: Four. The published effort figure covers three; chillers are added because the manuscript reports chiller accuracy, and an effort claim on a different inventory from the accuracy claim cannot be compared.
A11: Stages | B11: Eight. Stages 1–6 are the published normalised stages, unchanged, so a like-for-like comparison with Figure 6b stays possible. Stages 7–8 are work the current pipeline does that the 2026-05 workflow did not; they are shaded and can be excluded to reproduce the old scope.
A12: Operator | B12: Record the real person. One operator throughout is fine; state their Modelica/FMU experience in Notes on the first row.
A13: Observer | B13: Recorded by the operator, who is an author. Not independent; this is a stated limitation, not a claim of independence.
A14: Human active minutes | B14: Hands-on engineering only. Exclude breaks and any period spent waiting on an unattended machine. Rework counts, and the reason goes in Rework reason.
A15: Machine minutes | B15: Wall clock of the scripted compute, recorded separately. Never add it to human minutes.
A16: Scope equivalence | B16: The manual workflow must produce the same deliverables as the automated one — see the Deliverables sheet. A manual run that stops earlier is not a comparison.
... A20: Permitted claim once filled | B20: Author-performed, protocol-based time-and-motion study with timestamped logs. NOT independent — the operator is an author. Disclose that in Limitations.

Sheet Codebook
A1: Stage code sheet — stages 1–6 are the published definitions, 7–8 are additions
A3: Stage # | B3: Stage | C3: What counts as this stage | D3: In published Figure 6b scope?
A4: 1 | B4: Data loading and semantic mapping | C4: Read the historian export, identify which tag is which canonical role, resolve unit and sign conventions | D4: Yes
A5: 2 | B5: Valid model input table preparation | C5: Align channels onto one time base, screen invalid rows, reconstruct un-metered quantities, decide what counts as operating | D5: Yes
A6: 3 | B6: Modelica/FMU candidate setup | C6: Instantiate the candidate model types, expose the parameters to be fitted, verify the FMI interface | D6: Yes
A7: 4 | B7: FMU parameter search | C7: Fit each candidate's parameters and rank them by the declared rule | D7: Yes
A8: 5 | B8: Full-period refinement and validation | C8: Drive the selected model over the retained period and compute the reported metrics | D8: Yes
A9: 6 | B9: Paper tables and figures | C9: Produce the per-device table rows, figures and their source data | D9: Yes
A10: 7 | B10: Observability and evidence-grade review | C10: ADDED since 2026-05: check whether each channel is a measurement -- synthetic points, stuck status bits, frozen meters, impossible values, driver excitation -- and record the evidence grade | D10: No — added since 2026-05
A11: 8 | B11: Temporal split definition and audit | C11: ADDED since 2026-05: define identification / selection / test windows with buffers, confirm they are non-overlapping and comparable | D11: No — added since 2026-05

Sheet Sample
A1: Sampled devices — drawn from autofmu run sitea_e2e_20260804c
A2: Both sampled pumps are accepted in the current run. They are the extremes of drive excitation on this site — CDWP_03 is the only Site A pump whose drive genuinely varies, CHWP_01 barely moves — which is the property the manuscript has to qualify.
A4: Family | B4: Device | C4: Role in the sample | D4: Why this device
A5: Chiller | B5: CH_01 | C5: accepted_1 | D5: scored 5.99% test CVRMSE, skill 0.12, 29,086 operating rows
A6: Chiller | B6: CH_03 | C6: accepted_2 | D6: scored 4.49%, skill 0.22, the longest chiller record (50,889 rows)
A7: Chiller | B7: CH_05 | C7: blocked | D7: 40 operating rows: refused for insufficient evidence
A8: Cooling tower | B8: CT_01 | C8: accepted_1 | D8: scored, YorkCalc selected -- exercises the 27-coefficient path
A9: Cooling tower | B9: CT_05 | C9: accepted_2 | D9: scored, Merkel selected -- exercises the competing type
A10: Cooling tower | B10: CT_02 | C10: blocked | D10: 2,397 operating rows: no usable test window
A11: Pump | B11: CDWP_03 | C11: accepted_1 | D11: scored 9.98%, skill 0.60 — the only Site A pump whose drive genuinely varies (excitation 0.308); 51,490 rows
A12: Pump | B12: CHWP_01 | C12: accepted_2 | D12: scored 13.98%, skill 0.63, excitation 0.055 — the narrow-excitation case the manuscript must qualify
A13: Pump | B13: CDWP_02 | C13: blocked | D13: 2,369 operating rows: no usable selection window
A14: Heat exchanger | B14: HX_01 | C14: accepted_1 | D14: scored 9.33% on reconstructed heat, ConstantEffectiveness
A15: Heat exchanger | B15: HX_02 | C15: accepted_2 | D15: scored 7.97%, PlateEffectivenessNTU -- the competing type
A16: Heat exchanger | B16: HX_03 | C16: blocked | D16: target sensor dead: refused

Sheet Log
A1: Observed log — type into the green columns; grey columns are formulas
A2: Human start/end and Machine start/end take a full timestamp, e.g. 2026-08-05 09:14. Leave a row blank if the stage did not occur, and set Deliverable status to N/A.
A4: Record ID | B4: Date | C4: Operator ID | D4: Observer ID | E4: Workflow | F4: Family | G4: Device | H4: Order | I4: Stage # | J4: Stage | K4: Human start | L4: Human end | M4: Break min | N4: Human active min | O4: Machine start | P4: Machine end | Q4: Machine wall min | R4: Rework reason | S4: Deliverable status | T4: Evidence path | U4: Notes
A5: OBS-001 | B5: 46179 | C5: OP-001 | D5: OBS-001 | E5: Manual | F5: Chiller | G5: FAMILY_SETUP | H5: 0 | I5: 1 | J5: Data loading and semantic mapping | K5: 46179.356 | L5: 46179.385 | M5: 0 | N5: =IF(OR(K5="",L5=""),"",ROUND((L5-K5)*1440-N(M5),1)) | Q5: =IF(OR(O5="",P5=""),"",ROUND((P5-O5)*1440,1)) | S5: Complete
A6: OBS-002 | B6: 46179 | C6: OP-001 | D6: OBS-001 | E6: Manual | F6: Chiller | G6: FAMILY_SETUP | H6: 0 | I6: 2 | J6: Valid model input table preparation | K6: 46179.387 | L6: 46179.404 | M6: 0 | N6: =IF(OR(K6="",L6=""),"",ROUND((L6-K6)*1440-N(M6),1)) | Q6: =IF(OR(O6="",P6=""),"",ROUND((P6-O6)*1440,1)) | S6: Complete
A7: OBS-003 | B7: 46179 | C7: OP-001 | D7: OBS-001 | E7: Manual | F7: Chiller | G7: FAMILY_SETUP | H7: 0 | I7: 3 | J7: Modelica/FMU candidate setup | K7: 46179.406 | L7: 46179.441 | M7: 5 | N7: =IF(OR(K7="",L7=""),"",ROUND((L7-K7)*1440-N(M7),1)) | Q7: =IF(OR(O7="",P7=""),"",ROUND((P7-O7)*1440,1)) | S7: Complete
A8: OBS-004 | B8: 46179 | C8: OP-001 | D8: OBS-001 | E8: Manual | F8: Chiller | G8: FAMILY_SETUP | H8: 0 | I8: 4 | J8: FMU parameter search | K8: 46179.447 | L8: 46179.467 | M8: 0 | N8: =IF(OR(K8="",L8=""),"",ROUND((L8-K8)*1440-N(M8),1)) | Q8: =IF(OR(O8="",P8=""),"",ROUND((P8-O8)*1440,1)) | S8: Complete
A9: OBS-005 | B9: 46179 | C9: OP-001 | D9: OBS-001 | E9: Manual | F9: Chiller | G9: FAMILY_SETUP | H9: 0 | I9: 5 | J9: Full-period refinement and validation | K9: 46179.469 | L9: 46179.487 | M9: 0 | N9: =IF(OR(K9="",L9=""),"",ROUND((L9-K9)*1440-N(M9),1)) | Q9: =IF(OR(O9="",P9=""),"",ROUND((P9-O9)*1440,1)) | S9: Complete
A10: OBS-006 | B10: 46179 | C10: OP-001 | D10: OBS-001 | E10: Manual | F10: Chiller | G10: FAMILY_SETUP | H10: 0 | I10: 6 | J10: Paper tables and figures | K10: 46179.564 | L10: 46179.578 | M10: 0 | N10: =IF(OR(K10="",L10=""),"",ROUND((L10-K10)*1440-N(M10),1)) | Q10: =IF(OR(O10="",P10=""),"",ROUND((P10-O10)*1440,1)) | S10: Complete
A11: OBS-007 | B11: 46179 | C11: OP-001 | D11: OBS-001 | E11: Manual | F11: Chiller | G11: FAMILY_SETUP | H11: 0 | I11: 7 | J11: Observability and evidence-grade review | K11: 46179.581 | L11: 46179.605 | M11: 0 | N11: =IF(OR(K11="",L11=""),"",ROUND((L11-K11)*1440-N(M11),1)) | Q11: =IF(OR(O11="",P11=""),"",ROUND((P11-O11)*1440,1)) | S11: Complete
A12: OBS-008 | B12: 46179 | C12: OP-001 | D12: OBS-001 | E12: Manual | F12: Chiller | G12: FAMILY_SETUP | H12: 0 | I12: 8 | J12: Temporal split definition and audit | K12: 46179.608 | L12: 46179.626 | M12: 0 | N12: =IF(OR(K12="",L12=""),"",ROUND((L12-K12)*1440-N(M12),1)) | Q12: =IF(OR(O12="",P12=""),"",ROUND((P12-O12)*1440,1)) | S12: Complete
A13: OBS-009 | B13: 46179 | C13: OP-001 | D13: OBS-001 | E13: Manual | F13: Chiller | G13: CH_01 | H13: 1 | I13: 1 | J13: Data loading and semantic mapping | K13: 46179.632 | L13: 46179.653 | M13: 0 | N13: =IF(OR(K13="",L13=""),"",ROUND((L13-K13)*1440-N(M13),1)) | Q13: =IF(OR(O13="",P13=""),"",ROUND((P13-O13)*1440,1)) | S13: Complete
A14: OBS-010 | B14: 46179 | C14: OP-001 | D14: OBS-001 | E14: Manual | F14: Chiller | G14: CH_01 | H14: 1 | I14: 2 | J14: Valid model input table preparation | K14: 46179.657 | L14: 46179.685 | M14: 0 | N14: =IF(OR(K14="",L14=""),"",ROUND((L14-K14)*1440-N(M14),1)) | Q14: =IF(OR(O14="",P14=""),"",ROUND((P14-O14)*1440,1)) | S14: Complete
A15: OBS-011 | B15: 46179 | C15: OP-001 | D15: OBS-001 | E15: Manual | F15: Chiller | G15: CH_01 | H15: 1 | I15: 3 | J15: Modelica/FMU candidate setup | K15: 46179.692 | L15: 46179.727 | M15: 6 | N15: =IF(OR(K15="",L15=""),"",ROUND((L15-K15)*1440-N(M15),1)) | Q15: =IF(OR(O15="",P15=""),"",ROUND((P15-O15)*1440,1)) | S15: Complete
A16: OBS-012 | B16: 46181 | C16: OP-001 | D16: OBS-001 | E16: Manual | F16: Chiller | G16: CH_01 | H16: 1 | I16: 4 | J16: FMU parameter search | K16: 46181.352 | L16: 46181.429 | M16: 11 | N16: =IF(OR(K16="",L16=""),"",ROUND((L16-K16)*1440-N(M16),1)) | Q16: =IF(OR(O16="",P16=""),"",ROUND((P16-O16)*1440,1)) | S16: Complete
... A30: OBS-026 | B30: 46182 | C30: OP-001 | D30: OBS-001 | E30: Manual | F30: Chiller | G30: CH_05 | H30: 3 | I30: 2 | J30: Valid model input table preparation | K30: 46182.645 | L30: 46182.666 | M30: 0 | N30: =IF(OR(K30="",L30=""),"",ROUND((L30-K30)*1440-N(M30),1)) | Q30: =IF(OR(O30="",P30=""),"",ROUND((P30-O30)*1440,1)) | S30: Complete
A31: OBS-027 | E31: Manual | F31: Chiller | G31: CH_05 | H31: 3 | I31: 3 | J31: Modelica/FMU candidate setup | M31: 0 | N31: =IF(OR(K31="",L31=""),"",ROUND((L31-K31)*1440-N(M31),1)) | Q31: =IF(OR(O31="",P31=""),"",ROUND((P31-O31)*1440,1)) | S31: Not started
A32: OBS-028 | E32: Manual | F32: Chiller | G32: CH_05 | H32: 3 | I32: 4 | J32: FMU parameter search | M32: 0 | N32: =IF(OR(K32="",L32=""),"",ROUND((L32-K32)*1440-N(M32),1)) | Q32: =IF(OR(O32="",P32=""),"",ROUND((P32-O32)*1440,1)) | S32: Not started
A33: OBS-029 | E33: Manual | F33: Chiller | G33: CH_05 | H33: 3 | I33: 5 | J33: Full-period refinement and validation | M33: 0 | N33: =IF(OR(K33="",L33=""),"",ROUND((L33-K33)*1440-N(M33),1)) | Q33: =IF(OR(O33="",P33=""),"",ROUND((P33-O33)*1440,1)) | S33: Not started
A34: OBS-030 | E34: Manual | F34: Chiller | G34: CH_05 | H34: 3 | I34: 6 | J34: Paper tables and figures | M34: 0 | N34: =IF(OR(K34="",L34=""),"",ROUND((L34-K34)*1440-N(M34),1)) | Q34: =IF(OR(O34="",P34=""),"",ROUND((P34-O34)*1440,1)) | S34: Not started
A35: OBS-031 | B35: 46182 | C35: OP-001 | D35: OBS-001 | E35: Manual | F35: Chiller | G35: CH_05 | H35: 3 | I35: 7 | J35: Observability and evidence-grade review | K35: 46182.671 | L35: 46182.699 | M35: 0 | N35: =IF(OR(K35="",L35=""),"",ROUND((L35-K35)*1440-N(M35),1)) | Q35: =IF(OR(O35="",P35=""),"",ROUND((P35-O35)*1440,1)) | S35: Complete
A36: OBS-032 | B36: 46182 | C36: OP-001 | D36: OBS-001 | E36: Manual | F36: Chiller | G36: CH_05 | H36: 3 | I36: 8 | J36: Temporal split definition and audit | K36: 46182.701 | L36: 46182.718 | M36: 0 | N36: =IF(OR(K36="",L36=""),"",ROUND((L36-K36)*1440-N(M36),1)) | Q36: =IF(OR(O36="",P36=""),"",ROUND((P36-O36)*1440,1)) | S36: Blocked
A37: OBS-033 | E37: Auto | F37: Chiller | G37: FAMILY_SETUP | H37: 0 | I37: 1 | J37: Data loading and semantic mapping | M37: 0 | N37: =IF(OR(K37="",L37=""),"",ROUND((L37-K37)*1440-N(M37),1)) | Q37: =IF(OR(O37="",P37=""),"",ROUND((P37-O37)*1440,1)) | S37: Not started
A38: OBS-034 | E38: Auto | F38: Chiller | G38: FAMILY_SETUP | H38: 0 | I38: 2 | J38: Valid model input table preparation | M38: 0 | N38: =IF(OR(K38="",L38=""),"",ROUND((L38-K38)*1440-N(M38),1)) | Q38: =IF(OR(O38="",P38=""),"",ROUND((P38-O38)*1440,1)) | S38: Not started
A39: OBS-035 | E39: Auto | F39: Chiller | G39: FAMILY_SETUP | H39: 0 | I39: 3 | J39: Modelica/FMU candidate setup | M39: 0 | N39: =IF(OR(K39="",L39=""),"",ROUND((L39-K39)*1440-N(M39),1)) | Q39: =IF(OR(O39="",P39=""),"",ROUND((P39-O39)*1440,1)) | S39: Not started
A40: OBS-036 | E40: Auto | F40: Chiller | G40: FAMILY_SETUP | H40: 0 | I40: 4 | J40: FMU parameter search | M40: 0 | N40: =IF(OR(K40="",L40=""),"",ROUND((L40-K40)*1440-N(M40),1)) | Q40: =IF(OR(O40="",P40=""),"",ROUND((P40-O40)*1440,1)) | S40: Not started
A41: OBS-037 | E41: Auto | F41: Chiller | G41: FAMILY_SETUP | H41: 0 | I41: 5 | J41: Full-period refinement and validation | M41: 0 | N41: =IF(OR(K41="",L41=""),"",ROUND((L41-K41)*1440-N(M41),1)) | Q41: =IF(OR(O41="",P41=""),"",ROUND((P41-O41)*1440,1)) | S41: Not started
A42: OBS-038 | E42: Auto | F42: Chiller | G42: FAMILY_SETUP | H42: 0 | I42: 6 | J42: Paper tables and figures | M42: 0 | N42: =IF(OR(K42="",L42=""),"",ROUND((L42-K42)*1440-N(M42),1)) | Q42: =IF(OR(O42="",P42=""),"",ROUND((P42-O42)*1440,1)) | S42: Not started
A43: OBS-039 | E43: Auto | F43: Chiller | G43: FAMILY_SETUP | H43: 0 | I43: 7 | J43: Observability and evidence-grade review | M43: 0 | N43: =IF(OR(K43="",L43=""),"",ROUND((L43-K43)*1440-N(M43),1)) | Q43: =IF(OR(O43="",P43=""),"",ROUND((P43-O43)*1440,1)) | S43: Not started
A44: OBS-040 | E44: Auto | F44: Chiller | G44: FAMILY_SETUP | H44: 0 | I44: 8 | J44: Temporal split definition and audit | M44: 0 | N44: =IF(OR(K44="",L44=""),"",ROUND((L44-K44)*1440-N(M44),1)) | Q44: =IF(OR(O44="",P44=""),"",ROUND((P44-O44)*1440,1)) | S44: Not started
A45: OBS-041 | E45: Auto | F45: Chiller | G45: CH_01 | H45: 1 | I45: 1 | J45: Data loading and semantic mapping | M45: 0 | N45: =IF(OR(K45="",L45=""),"",ROUND((L45-K45)*1440-N(M45),1)) | Q45: =IF(OR(O45="",P45=""),"",ROUND((P45-O45)*1440,1)) | S45: Not started
A46: OBS-042 | E46: Auto | F46: Chiller | G46: CH_01 | H46: 1 | I46: 2 | J46: Valid model input table preparation | M46: 0 | N46: =IF(OR(K46="",L46=""),"",ROUND((L46-K46)*1440-N(M46),1)) | Q46: =IF(OR(O46="",P46=""),"",ROUND((P46-O46)*1440,1)) | S46: Not started
A47: OBS-043 | E47: Auto | F47: Chiller | G47: CH_01 | H47: 1 | I47: 3 | J47: Modelica/FMU candidate setup | M47: 0 | N47: =IF(OR(K47="",L47=""),"",ROUND((L47-K47)*1440-N(M47),1)) | Q47: =IF(OR(O47="",P47=""),"",ROUND((P47-O47)*1440,1)) | S47: Not started
A48: OBS-044 | E48: Auto | F48: Chiller | G48: CH_01 | H48: 1 | I48: 4 | J48: FMU parameter search | M48: 0 | N48: =IF(OR(K48="",L48=""),"",ROUND((L48-K48)*1440-N(M48),1)) | Q48: =IF(OR(O48="",P48=""),"",ROUND((P48-O48)*1440,1)) | S48: Not started
... A68: OBS-064 | E68: Auto | F68: Chiller | G68: CH_05 | H68: 3 | I68: 8 | J68: Temporal split definition and audit | M68: 0 | N68: =IF(OR(K68="",L68=""),"",ROUND((L68-K68)*1440-N(M68),1)) | Q68: =IF(OR(O68="",P68=""),"",ROUND((P68-O68)*1440,1)) | S68: Not started
A69: OBS-065 | B69: 46183 | C69: OP-001 | D69: OBS-001 | E69: Manual | F69: Cooling tower | G69: FAMILY_SETUP | H69: 0 | I69: 1 | J69: Data loading and semantic mapping | K69: 46183.363 | L69: 46183.384 | M69: 0 | N69: =IF(OR(K69="",L69=""),"",ROUND((L69-K69)*1440-N(M69),1)) | Q69: =IF(OR(O69="",P69=""),"",ROUND((P69-O69)*1440,1)) | S69: Complete
A70: OBS-066 | B70: 46183 | C70: OP-001 | D70: OBS-001 | E70: Manual | F70: Cooling tower | G70: FAMILY_SETUP | H70: 0 | I70: 2 | J70: Valid model input table preparation | K70: 46183.387 | L70: 46183.408 | M70: 0 | N70: =IF(OR(K70="",L70=""),"",ROUND((L70-K70)*1440-N(M70),1)) | Q70: =IF(OR(O70="",P70=""),"",ROUND((P70-O70)*1440,1)) | S70: Complete
A71: OBS-067 | B71: 46183 | C71: OP-001 | D71: OBS-001 | E71: Manual | F71: Cooling tower | G71: FAMILY_SETUP | H71: 0 | I71: 3 | J71: Modelica/FMU candidate setup | K71: 46183.411 | L71: 46183.458 | M71: 8 | N71: =IF(OR(K71="",L71=""),"",ROUND((L71-K71)*1440-N(M71),1)) | Q71: =IF(OR(O71="",P71=""),"",ROUND((P71-O71)*1440,1)) | S71: Complete
A72: OBS-068 | B72: 46183 | C72: OP-001 | D72: OBS-001 | E72: Manual | F72: Cooling tower | G72: FAMILY_SETUP | H72: 0 | I72: 4 | J72: FMU parameter search | K72: 46183.462 | L72: 46183.497 | M72: 6 | N72: =IF(OR(K72="",L72=""),"",ROUND((L72-K72)*1440-N(M72),1)) | Q72: =IF(OR(O72="",P72=""),"",ROUND((P72-O72)*1440,1)) | S72: Complete
A73: OBS-069 | B73: 46184 | C73: OP-001 | D73: OBS-001 | E73: Manual | F73: Cooling tower | G73: FAMILY_SETUP | H73: 0 | I73: 5 | J73: Full-period refinement and validation | K73: 46184.358 | L73: 46184.383 | M73: 0 | N73: =IF(OR(K73="",L73=""),"",ROUND((L73-K73)*1440-N(M73),1)) | Q73: =IF(OR(O73="",P73=""),"",ROUND((P73-O73)*1440,1)) | S73: Complete
...

Sheet Deliverables
A1: Deliverable equivalence — the manual run must produce all of these too
A2: A manual workflow that stops before these exist is not a comparison. Tick each one for both workflows as you go.
A4: Family | B4: Device | C4: Role | D4: Deliverable | E4: Manual done | F4: Auto done | G4: Evidence path | H4: Notes
A5: Chiller | B5: CH_01 | C5: accepted_1 | D5: Clean input table
A6: Chiller | B6: CH_01 | C6: accepted_1 | D6: Candidate comparison / selection record
A7: Chiller | B7: CH_01 | C7: accepted_1 | D7: Fitted parameter set
A8: Chiller | B8: CH_01 | C8: accepted_1 | D8: Selected Modelica source
A9: Chiller | B9: CH_01 | C9: accepted_1 | D9: Exported FMU
A10: Chiller | B10: CH_01 | C10: accepted_1 | D10: Test-window and full-period metrics
A11: Chiller | B11: CH_01 | C11: accepted_1 | D11: Time series / figure
A12: Chiller | B12: CH_01 | C12: accepted_1 | D12: Artefact manifest
A13: Chiller | B13: CH_03 | C13: accepted_2 | D13: Clean input table
A14: Chiller | B14: CH_03 | C14: accepted_2 | D14: Candidate comparison / selection record
A15: Chiller | B15: CH_03 | C15: accepted_2 | D15: Fitted parameter set
A16: Chiller | B16: CH_03 | C16: accepted_2 | D16: Selected Modelica source
... A76: Heat exchanger | B76: HX_03 | C76: blocked | D76: Explicit statement that no validated model or FMU is claimed

Sheet Summary
A1: Summary — every cell is a formula over Log. Nothing here is an estimate.
A2: Blank until Log is filled. Full-inventory hours use the current Site A counts; edit the accepted/blocked columns if the pipeline result changes.
A4: Family | B4: Workflow | C4: Inventory n | D4: Accepted n | E4: Blocked n | F4: Setup h | G4: Accepted device 1 h | H4: Accepted device 2 h | I4: Accepted marginal h | J4: Blocked marginal h | K4: Full inventory h | L4: Learning effect (1 − d2/d1)
A5: Chiller | B5: Manual | C5: 7 | D5: 3 | E5: 4 | F5: =IF(SUMIFS(Log!$N$5:$N$260,Log!$F$5:$F$260,"Chiller",Log!$E$5:$E$260,"Manual",Log!$G$5:$G$260,"FAMILY_SETUP")=0,"",ROUND(SUMIFS(Log!$N$5:$N$260,Log!$F$5:$F$260,"Chiller",Log!$E$5:$E$260,"Manual",Log!$G$5:$G$260,"FAMILY_SETUP")/60,3)) | G5: =IF(SUMIFS(Log!$N$5:$N$260,Log!$F$5:$F$260,"Chiller",Log!$E$5:$E$260,"Manual",Log!$G$5:$G$260,"CH_01")=0,"",ROUND(SUMIFS(Log!$N$5:$N$260,Log!$F$5:$F$260,"Chiller",Log!$E$5:$E$260,"Manual",Log!$G$5:$G$260,"CH_01")/60,3)) | H5: =IF(SUMIFS(Log!$N$5:$N$260,Log!$F$5:$F$260,"Chiller",Log!$E$5:$E$260,"Manual",Log!$G$5:$G$260,"CH_03")=0,"",ROUND(SUMIFS(Log!$N$5:$N$260,Log!$F$5:$F$260,"Chiller",Log!$E$5:$E$260,"Manual",Log!$G$5:$G$260,"CH_03")/60,3)) | I5: =IF(COUNT(G5:H5)=0,"",ROUND(AVERAGE(G5:H5),3)) | J5: =IF(SUMIFS(Log!$N$5:$N$260,Log!$F$5:$F$260,"Chiller",Log!$E$5:$E$260,"Manual",Log!$G$5:$G$260,"CH_05")=0,"",ROUND(SUMIFS(Log!$N$5:$N$260,Log!$F$5:$F$260,"Chiller",Log!$E$5:$E$260,"Manual",Log!$G$5:$G$260,"CH_05")/60,3)) | K5: =IF(I5="","",ROUND(N(F5)+D5*I5+E5*N(J5),2)) | L5: =IF(OR(G5=0,G5=""),"",ROUND(1-H5/G5,3))
A6: Chiller | B6: Auto | C6: 7 | D6: 3 | E6: 4 | F6: =IF(SUMIFS(Log!$N$5:$N$260,Log!$F$5:$F$260,"Chiller",Log!$E$5:$E$260,"Auto",Log!$G$5:$G$260,"FAMILY_SETUP")=0,"",ROUND(SUMIFS(Log!$N$5:$N$260,Log!$F$5:$F$260,"Chiller",Log!$E$5:$E$260,"Auto",Log!$G$5:$G$260,"FAMILY_SETUP")/60,3)) | G6: =IF(SUMIFS(Log!$N$5:$N$260,Log!$F$5:$F$260,"Chiller",Log!$E$5:$E$260,"Auto",Log!$G$5:$G$260,"CH_01")=0,"",ROUND(SUMIFS(Log!$N$5:$N$260,Log!$F$5:$F$260,"Chiller",Log!$E$5:$E$260,"Auto",Log!$G$5:$G$260,"CH_01")/60,3)) | H6: =IF(SUMIFS(Log!$N$5:$N$260,Log!$F$5:$F$260,"Chiller",Log!$E$5:$E$260,"Auto",Log!$G$5:$G$260,"CH_03")=0,"",ROUND(SUMIFS(Log!$N$5:$N$260,Log!$F$5:$F$260,"Chiller",Log!$E$5:$E$260,"Auto",Log!$G$5:$G$260,"CH_03")/60,3)) | I6: =IF(COUNT(G6:H6)=0,"",ROUND(AVERAGE(G6:H6),3)) | J6: =IF(SUMIFS(Log!$N$5:$N$260,Log!$F$5:$F$260,"Chiller",Log!$E$5:$E$260,"Auto",Log!$G$5:$G$260,"CH_05")=0,"",ROUND(SUMIFS(Log!$N$5:$N$260,Log!$F$5:$F$260,"Chiller",Log!$E$5:$E$260,"Auto",Log!$G$5:$G$260,"CH_05")/60,3)) | K6: =IF(I6="","",ROUND(N(F6)+D6*I6+E6*N(J6),2)) | L6: =IF(OR(G6=0,G6=""),"",ROUND(1-H6/G6,3))
A7: Cooling tower | B7: Manual | C7: 7 | D7: 4 | E7: 3 | F7: =IF(SUMIFS(Log!$N$5:$N$260,Log!$F$5:$F$260,"Cooling tower",Log!$E$5:$E$260,"Manual",Log!$G$5:$G$260,"FAMILY_SETUP")=0,"",ROUND(SUMIFS(Log!$N$5:$N$260,Log!$F$5:$F$260,"Cooling tower",Log!$E$5:$E$260,"Manual",Log!$G$5:$G$260,"FAMILY_SETUP")/60,3)) | G7: =IF(SUMIFS(Log!$N$5:$N$260,Log!$F$5:$F$260,"Cooling tower",Log!$E$5:$E$260,"Manual",Log!$G$5:$G$260,"CT_01")=0,"",ROUND(SUMIFS(Log!$N$5:$N$260,Log!$F$5:$F$260,"Cooling tower",Log!$E$5:$E$260,"Manual",Log!$G$5:$G$260,"CT_01")/60,3)) | H7: =IF(SUMIFS(Log!$N$5:$N$260,Log!$F$5:$F$260,"Cooling tower",Log!$E$5:$E$260,"Manual",Log!$G$5:$G$260,"CT_05")=0,"",ROUND(SUMIFS(Log!$N$5:$N$260,Log!$F$5:$F$260,"Cooling tower",Log!$E$5:$E$260,"Manual",Log!$G$5:$G$260,"CT_05")/60,3)) | I7: =IF(COUNT(G7:H7)=0,"",ROUND(AVERAGE(G7:H7),3)) | J7: =IF(SUMIFS(Log!$N$5:$N$260,Log!$F$5:$F$260,"Cooling tower",Log!$E$5:$E$260,"Manual",Log!$G$5:$G$260,"CT_02")=0,"",ROUND(SUMIFS(Log!$N$5:$N$260,Log!$F$5:$F$260,"Cooling tower",Log!$E$5:$E$260,"Manual",Log!$G$5:$G$260,"CT_02")/60,3)) | K7: =IF(I7="","",ROUND(N(F7)+D7*I7+E7*N(J7),2)) | L7: =IF(OR(G7=0,G7=""),"",ROUND(1-H7/G7,3))
A8: Cooling tower | B8: Auto | C8: 7 | D8: 4 | E8: 3 | F8: =IF(SUMIFS(Log!$N$5:$N$260,Log!$F$5:$F$260,"Cooling tower",Log!$E$5:$E$260,"Auto",Log!$G$5:$G$260,"FAMILY_SETUP")=0,"",ROUND(SUMIFS(Log!$N$5:$N$260,Log!$F$5:$F$260,"Cooling tower",Log!$E$5:$E$260,"Auto",Log!$G$5:$G$260,"FAMILY_SETUP")/60,3)) | G8: =IF(SUMIFS(Log!$N$5:$N$260,Log!$F$5:$F$260,"Cooling tower",Log!$E$5:$E$260,"Auto",Log!$G$5:$G$260,"CT_01")=0,"",ROUND(SUMIFS(Log!$N$5:$N$260,Log!$F$5:$F$260,"Cooling tower",Log!$E$5:$E$260,"Auto",Log!$G$5:$G$260,"CT_01")/60,3)) | H8: =IF(SUMIFS(Log!$N$5:$N$260,Log!$F$5:$F$260,"Cooling tower",Log!$E$5:$E$260,"Auto",Log!$G$5:$G$260,"CT_05")=0,"",ROUND(SUMIFS(Log!$N$5:$N$260,Log!$F$5:$F$260,"Cooling tower",Log!$E$5:$E$260,"Auto",Log!$G$5:$G$260,"CT_05")/60,3)) | I8: =IF(COUNT(G8:H8)=0,"",ROUND(AVERAGE(G8:H8),3)) | J8: =IF(SUMIFS(Log!$N$5:$N$260,Log!$F$5:$F$260,"Cooling tower",Log!$E$5:$E$260,"Auto",Log!$G$5:$G$260,"CT_02")=0,"",ROUND(SUMIFS(Log!$N$5:$N$260,Log!$F$5:$F$260,"Cooling tower",Log!$E$5:$E$260,"Auto",Log!$G$5:$G$260,"CT_02")/60,3)) | K8: =IF(I8="","",ROUND(N(F8)+D8*I8+E8*N(J8),2)) | L8: =IF(OR(G8=0,G8=""),"",ROUND(1-H8/G8,3))
A9: Pump | B9: Manual | C9: 17 | D9: 10 | E9: 7 | F9: =IF(SUMIFS(Log!$N$5:$N$260,Log!$F$5:$F$260,"Pump",Log!$E$5:$E$260,"Manual",Log!$G$5:$G$260,"FAMILY_SETUP")=0,"",ROUND(SUMIFS(Log!$N$5:$N$260,Log!$F$5:$F$260,"Pump",Log!$E$5:$E$260,"Manual",Log!$G$5:$G$260,"FAMILY_SETUP")/60,3)) | G9: =IF(SUMIFS(Log!$N$5:$N$260,Log!$F$5:$F$260,"Pump",Log!$E$5:$E$260,"Manual",Log!$G$5:$G$260,"CDWP_03")=0,"",ROUND(SUMIFS(Log!$N$5:$N$260,Log!$F$5:$F$260,"Pump",Log!$E$5:$E$260,"Manual",Log!$G$5:$G$260,"CDWP_03")/60,3)) | H9: =IF(SUMIFS(Log!$N$5:$N$260,Log!$F$5:$F$260,"Pump",Log!$E$5:$E$260,"Manual",Log!$G$5:$G$260,"CHWP_01")=0,"",ROUND(SUMIFS(Log!$N$5:$N$260,Log!$F$5:$F$260,"Pump",Log!$E$5:$E$260,"Manual",Log!$G$5:$G$260,"CHWP_01")/60,3)) | I9: =IF(COUNT(G9:H9)=0,"",ROUND(AVERAGE(G9:H9),3)) | J9: =IF(SUMIFS(Log!$N$5:$N$260,Log!$F$5:$F$260,"Pump",Log!$E$5:$E$260,"Manual",Log!$G$5:$G$260,"CDWP_02")=0,"",ROUND(SUMIFS(Log!$N$5:$N$260,Log!$F$5:$F$260,"Pump",Log!$E$5:$E$260,"Manual",Log!$G$5:$G$260,"CDWP_02")/60,3)) | K9: =IF(I9="","",ROUND(N(F9)+D9*I9+E9*N(J9),2)) | L9: =IF(OR(G9=0,G9=""),"",ROUND(1-H9/G9,3))
A10: Pump | B10: Auto | C10: 17 | D10: 10 | E10: 7 | F10: =IF(SUMIFS(Log!$N$5:$N$260,Log!$F$5:$F$260,"Pump",Log!$E$5:$E$260,"Auto",Log!$G$5:$G$260,"FAMILY_SETUP")=0,"",ROUND(SUMIFS(Log!$N$5:$N$260,Log!$F$5:$F$260,"Pump",Log!$E$5:$E$260,"Auto",Log!$G$5:$G$260,"FAMILY_SETUP")/60,3)) | G10: =IF(SUMIFS(Log!$N$5:$N$260,Log!$F$5:$F$260,"Pump",Log!$E$5:$E$260,"Auto",Log!$G$5:$G$260,"CDWP_03")=0,"",ROUND(SUMIFS(Log!$N$5:$N$260,Log!$F$5:$F$260,"Pump",Log!$E$5:$E$260,"Auto",Log!$G$5:$G$260,"CDWP_03")/60,3)) | H10: =IF(SUMIFS(Log!$N$5:$N$260,Log!$F$5:$F$260,"Pump",Log!$E$5:$E$260,"Auto",Log!$G$5:$G$260,"CHWP_01")=0,"",ROUND(SUMIFS(Log!$N$5:$N$260,Log!$F$5:$F$260,"Pump",Log!$E$5:$E$260,"Auto",Log!$G$5:$G$260,"CHWP_01")/60,3)) | I10: =IF(COUNT(G10:H10)=0,"",ROUND(AVERAGE(G10:H10),3)) | J10: =IF(SUMIFS(Log!$N$5:$N$260,Log!$F$5:$F$260,"Pump",Log!$E$5:$E$260,"Auto",Log!$G$5:$G$260,"CDWP_02")=0,"",ROUND(SUMIFS(Log!$N$5:$N$260,Log!$F$5:$F$260,"Pump",Log!$E$5:$E$260,"Auto",Log!$G$5:$G$260,"CDWP_02")/60,3)) | K10: =IF(I10="","",ROUND(N(F10)+D10*I10+E10*N(J10),2)) | L10: =IF(OR(G10=0,G10=""),"",ROUND(1-H10/G10,3))
A11: Heat exchanger | B11: Manual | C11: 3 | D11: 2 | E11: 1 | F11: =IF(SUMIFS(Log!$N$5:$N$260,Log!$F$5:$F$260,"Heat exchanger",Log!$E$5:$E$260,"Manual",Log!$G$5:$G$260,"FAMILY_SETUP")=0,"",ROUND(SUMIFS(Log!$N$5:$N$260,Log!$F$5:$F$260,"Heat exchanger",Log!$E$5:$E$260,"Manual",Log!$G$5:$G$260,"FAMILY_SETUP")/60,3)) | G11: =IF(SUMIFS(Log!$N$5:$N$260,Log!$F$5:$F$260,"Heat exchanger",Log!$E$5:$E$260,"Manual",Log!$G$5:$G$260,"HX_01")=0,"",ROUND(SUMIFS(Log!$N$5:$N$260,Log!$F$5:$F$260,"Heat exchanger",Log!$E$5:$E$260,"Manual",Log!$G$5:$G$260,"HX_01")/60,3)) | H11: =IF(SUMIFS(Log!$N$5:$N$260,Log!$F$5:$F$260,"Heat exchanger",Log!$E$5:$E$260,"Manual",Log!$G$5:$G$260,"HX_02")=0,"",ROUND(SUMIFS(Log!$N$5:$N$260,Log!$F$5:$F$260,"Heat exchanger",Log!$E$5:$E$260,"Manual",Log!$G$5:$G$260,"HX_02")/60,3)) | I11: =IF(COUNT(G11:H11)=0,"",ROUND(AVERAGE(G11:H11),3)) | J11: =IF(SUMIFS(Log!$N$5:$N$260,Log!$F$5:$F$260,"Heat exchanger",Log!$E$5:$E$260,"Manual",Log!$G$5:$G$260,"HX_03")=0,"",ROUND(SUMIFS(Log!$N$5:$N$260,Log!$F$5:$F$260,"Heat exchanger",Log!$E$5:$E$260,"Manual",Log!$G$5:$G$260,"HX_03")/60,3)) | K11: =IF(I11="","",ROUND(N(F11)+D11*I11+E11*N(J11),2)) | L11: =IF(OR(G11=0,G11=""),"",ROUND(1-H11/G11,3))
A12: Heat exchanger | B12: Auto | C12: 3 | D12: 2 | E12: 1 | F12: =IF(SUMIFS(Log!$N$5:$N$260,Log!$F$5:$F$260,"Heat exchanger",Log!$E$5:$E$260,"Auto",Log!$G$5:$G$260,"FAMILY_SETUP")=0,"",ROUND(SUMIFS(Log!$N$5:$N$260,Log!$F$5:$F$260,"Heat exchanger",Log!$E$5:$E$260,"Auto",Log!$G$5:$G$260,"FAMILY_SETUP")/60,3)) | G12: =IF(SUMIFS(Log!$N$5:$N$260,Log!$F$5:$F$260,"Heat exchanger",Log!$E$5:$E$260,"Auto",Log!$G$5:$G$260,"HX_01")=0,"",ROUND(SUMIFS(Log!$N$5:$N$260,Log!$F$5:$F$260,"Heat exchanger",Log!$E$5:$E$260,"Auto",Log!$G$5:$G$260,"HX_01")/60,3)) | H12: =IF(SUMIFS(Log!$N$5:$N$260,Log!$F$5:$F$260,"Heat exchanger",Log!$E$5:$E$260,"Auto",Log!$G$5:$G$260,"HX_02")=0,"",ROUND(SUMIFS(Log!$N$5:$N$260,Log!$F$5:$F$260,"Heat exchanger",Log!$E$5:$E$260,"Auto",Log!$G$5:$G$260,"HX_02")/60,3)) | I12: =IF(COUNT(G12:H12)=0,"",ROUND(AVERAGE(G12:H12),3)) | J12: =IF(SUMIFS(Log!$N$5:$N$260,Log!$F$5:$F$260,"Heat exchanger",Log!$E$5:$E$260,"Auto",Log!$G$5:$G$260,"HX_03")=0,"",ROUND(SUMIFS(Log!$N$5:$N$260,Log!$F$5:$F$260,"Heat exchanger",Log!$E$5:$E$260,"Auto",Log!$G$5:$G$260,"HX_03")/60,3)) | K12: =IF(I12="","",ROUND(N(F12)+D12*I12+E12*N(J12),2)) | L12: =IF(OR(G12=0,G12=""),"",ROUND(1-H12/G12,3))
A14: Site A totals
A15: Quantity | B15: Manual h | C15: Auto human h | D15: Saved h | E15: Reduction
A16: Full inventory (stages 1–8) | B16: =IF(COUNT(K5:K12)=0,"",ROUND(SUMIF(B5:B12,"Manual",K5:K12),2)) | C16: =IF(COUNT(K5:K12)=0,"",ROUND(SUMIF(B5:B12,"Auto",K5:K12),2)) | D16: =IF(B16="","",ROUND(B16-C16,2)) | E16: =IF(OR(B16="",B16=0),"",ROUND(1-C16/B16,4))
A18: To reproduce the published Figure 6b scope, filter Log to stages 1–6 and to the cooling tower, pump and heat exchanger families before reading these totals. Machine wall minutes (Log column Q) are reported separately and are never added to human hours.
